<?xml version="1.0" ?>
<robot name="ur10e">
  <link name="world"/>
  <link name="base">
    <inertial>
      <mass value="4.0"/>
      <origin xyz="0.0 0.0 0.0" rpy="0 0 0"/>
      <inertia ixx="0.0061063308908" iyy="0.0061063308908" izz="0.01125" ixy="0.0" ixz="0.0" iyz="0.0"/>
    </inertial>
  </link>
  <link name="shoulder_link">
    <inertial>
      <mass value="7.778"/>
      <origin xyz="0.0 0.0 0.0" rpy="0 0 0"/>
      <inertia ixx="0.0314743" iyy="0.0314743" izz="0.0218756" ixy="0.0" ixz="0.0" iyz="0.0"/>
    </inertial>
  </link>
  <link name="upper_arm_link">
    <inertial>
      <mass value="12.93"/>
      <origin xyz="0.0 0.0 0.3065" rpy="0 0 0"/>
      <inertia ixx="0.423074" iyy="0.423074" izz="0.0363656" ixy="0.0" ixz="0.0" iyz="0.0"/>
    </inertial>
  </link>
  <link name="forearm_link">
    <inertial>
      <mass value="3.87"/>
      <origin xyz="0.0 0.0 0.2855" rpy="0 0 0"/>
      <inertia ixx="0.11059" iyy="0.11059" izz="0.0108844" ixy="0.0" ixz="0.0" iyz="0.0"/>
    </inertial>
  </link>
  <link name="wrist_1_link">
    <inertial>
      <mass value="1.96"/>
      <origin xyz="0.0 0.135 0.0" rpy="0 0 0"/>
      <inertia ixx="0.0055125" iyy="0.00510825" izz="0.00510825" ixy="0.0" ixz="0.0" iyz="0.0"/>
    </inertial>
  </link>
  <link name="wrist_2_link">
    <inertial>
      <mass value="1.96"/>
      <origin xyz="0.0 0.0 0.12" rpy="0 0 0"/>
      <inertia ixx="0.0055125" iyy="0.00510825" izz="0.00510825" ixy="0.0" ixz="0.0" iyz="0.0"/>
    </inertial>
  </link>
  <link name="wrist_3_link">
    <inertial>
      <mass value="0.202"/>
      <origin xyz="0.0 0.092 0.0" rpy="0 0 0"/>
      <inertia ixx="0.000204525" iyy="0.000144346" izz="0.000144346" ixy="0.0" ixz="0.0" iyz="0.0"/>
    </inertial>
  </link>
  <joint name="shoulder_pan_joint" type="continuous">
    <parent link="base"/>
    <child link="shoulder_link"/>
    <origin xyz="0.0 0.0 0.181" rpy="0 0 0"/>
    <axis xyz="0.0 0.0 1.0"/>
  </joint>
  <joint name="shoulder_lift_joint" type="continuous">
    <parent link="shoulder_link"/>
    <child link="upper_arm_link"/>
    <origin xyz="0.0 0.176 0.0" rpy="0 0 0"/>
    <axis xyz="0.0 1.0 0.0"/>
  </joint>
  <joint name="elbow_joint" type="continuous">
    <parent link="upper_arm_link"/>
    <child link="forearm_link"/>
    <origin xyz="0.0 -0.137 0.613" rpy="0 0 0"/>
    <axis xyz="0.0 1.0 0.0"/>
  </joint>
  <joint name="wrist_1_joint" type="continuous">
    <parent link="forearm_link"/>
    <child link="wrist_1_link"/>
    <origin xyz="0.0 0.0 0.571" rpy="0 0 0"/>
    <axis xyz="0.0 1.0 0.0"/>
  </joint>
  <joint name="wrist_2_joint" type="continuous">
    <parent link="wrist_1_link"/>
    <child link="wrist_2_link"/>
    <origin xyz="0.0 0.135 0.0" rpy="0 0 0"/>
    <axis xyz="0.0 0.0 1.0"/>
  </joint>
  <joint name="wrist_3_joint" type="continuous">
    <parent link="wrist_2_link"/>
    <child link="wrist_3_link"/>
    <origin xyz="0.0 0.0 0.12" rpy="0 0 0"/>
    <axis xyz="0.0 1.0 0.0"/>
  </joint>
</robot>
