<?xml version="1.0" ?>
<robot name="ur10">
  <link name="base_link">
    <inertial>
      <mass value="4.0"/>
      <origin xyz="0.0 0.0 0.0" rpy="0 0 0"/>
      <inertia ixx="0.0061063308908" iyy="0.0061063308908" izz="0.01125" ixy="0.0" ixz="0.0" iyz="0.0"/>
    </inertial>
  </link>
  <link name="shoulder_link">
    <inertial>
      <mass value="7.778"/>
      <origin xyz="0.0 0.0 0.0" rpy="0 0 0"/>
      <inertia ixx="0.0314743125769" iyy="0.0314743125769" izz="0.021875625" ixy="0.0" ixz="0.0" iyz="0.0"/>
    </inertial>
  </link>
  <link name="upper_arm_link">
    <inertial>
      <mass value="12.93"/>
      <origin xyz="0.0 0.0 0.306" rpy="0 0 0"/>
      <inertia ixx="0.421753803798" iyy="0.421753803798" izz="0.036365625" ixy="0.0" ixz="0.0" iyz="0.0"/>
    </inertial>
  </link>
  <link name="forearm_link">
    <inertial>
      <mass value="3.87"/>
      <origin xyz="0.0 0.0 0.28615" rpy="0 0 0"/>
      <inertia ixx="0.111069694097" iyy="0.111069694097" izz="0.010884375" ixy="0.0" ixz="0.0" iyz="0.0"/>
    </inertial>
  </link>
  <link name="wrist_1_link">
    <inertial>
      <mass value="1.96"/>
      <origin xyz="0.0 0.0 0.0" rpy="0 0 0"/>
      <inertia ixx="0.0051082479567" iyy="0.0051082479567" izz="0.0055125" ixy="0.0" ixz="0.0" iyz="0.0"/>
    </inertial>
  </link>
  <link name="wrist_2_link">
    <inertial>
      <mass value="1.96"/>
      <origin xyz="0.0 0.0 0.0" rpy="0 0 0"/>
      <inertia ixx="0.0051082479567" iyy="0.0051082479567" izz="0.0055125" ixy="0.0" ixz="0.0" iyz="0.0"/>
    </inertial>
  </link>
  <link name="wrist_3_link">
    <inertial>
      <mass value="0.202"/>
      <origin xyz="0.0 0.0 0.0" rpy="0 0 0"/>
      <inertia ixx="0.000526462289415" iyy="0.000526462289415" izz="0.000568125" ixy="0.0" ixz="0.0" iyz="0.0"/>
    </inertial>
  </link>
  <link name="ee_link"/>
  <link name="base"/>
  <link name="tool0"/>
  <link name="world"/>
  <joint name="shoulder_pan_joint" type="revolute">
    <parent link="base_link"/>
    <child link="shoulder_link"/>
    <origin xyz="0.0 0.0 0.1273" rpy="0 0 0"/>
    <axis xyz="0.0 0.0 1.0"/>
    <limit lower="-6.28318530718" upper="6.28318530718" effort="330.0" velocity="2.16"/>
  </joint>
  <joint name="shoulder_lift_joint" type="revolute">
    <parent link="shoulder_link"/>
    <child link="upper_arm_link"/>
    <origin xyz="0.0 0.220941 0.0" rpy="0 0 0"/>
    <axis xyz="0.0 1.0 0.0"/>
    <limit lower="-6.28318530718" upper="6.28318530718" effort="330.0" velocity="2.16"/>
  </joint>
  <joint name="elbow_joint" type="revolute">
    <parent link="upper_arm_link"/>
    <child link="forearm_link"/>
    <origin xyz="0.0 -0.1719 0.612" rpy="0 0 0"/>
    <axis xyz="0.0 1.0 0.0"/>
    <limit lower="-3.14159265359" upper="3.14159265359" effort="150.0" velocity="3.15"/>
  </joint>
  <joint name="wrist_1_joint" type="revolute">
    <parent link="forearm_link"/>
    <child link="wrist_1_link"/>
    <origin xyz="0.0 0.0 0.5723" rpy="0 0 0"/>
    <axis xyz="0.0 1.0 0.0"/>
    <limit lower="-6.28318530718" upper="6.28318530718" effort="54.0" velocity="3.2"/>
  </joint>
  <joint name="wrist_2_joint" type="revolute">
    <parent link="wrist_1_link"/>
    <child link="wrist_2_link"/>
    <origin xyz="0.0 0.1149 0.0" rpy="0 0 0"/>
    <axis xyz="0.0 0.0 1.0"/>
    <limit lower="-6.28318530718" upper="6.28318530718" effort="54.0" velocity="3.2"/>
  </joint>
  <joint name="wrist_3_joint" type="revolute">
    <parent link="wrist_2_link"/>
    <child link="wrist_3_link"/>
    <origin xyz="0.0 0.0 0.1157" rpy="0 0 0"/>
    <axis xyz="0.0 1.0 0.0"/>
    <limit lower="-6.28318530718" upper="6.28318530718" effort="54.0" velocity="3.2"/>
  </joint>
  <joint name="ee_fixed_joint" type="fixed">
    <parent link="wrist_3_link"/>
    <child link="ee_link"/>
    <origin xyz="0.0 0.0922 0.0" rpy="0 0 0"/>
    <axis xyz="0 0 1"/>
  </joint>
  <joint name="base_link-base_fixed_joint" type="fixed">
    <parent link="base_link"/>
    <child link="base"/>
    <origin xyz="0.0 0.0 0.0" rpy="0 0 0"/>
    <axis xyz="0 0 1"/>
  </joint>
  <joint name="wrist_3_link-tool0_fixed_joint" type="fixed">
    <parent link="wrist_3_link"/>
    <child link="tool0"/>
    <origin xyz="0.0 0.0922 0.0" rpy="0 0 0"/>
    <axis xyz="0 0 1"/>
  </joint>
  <joint name="world_joint" type="fixed">
    <parent link="world"/>
    <child link="base_link"/>
    <origin xyz="0.0 0.0 0.0" rpy="0 0 0"/>
    <axis xyz="0 0 1"/>
  </joint>
</robot>
